<?xml version="1.0" encoding="utf-8"?>
<!-- This URDF was automatically created by SolidWorks to URDF Exporter! Originally created by Stephen Brawner (brawner@gmail.com) 
     Commit Version: 1.6.0-4-g7f85cfe  Build Version: 1.6.7995.38578
     For more information, please see http://wiki.ros.org/sw_urdf_exporter -->
<robot
  name="urdf">
  <link
    name="base_link">
    <inertial>
      <origin
        xyz="0 0 0"
        rpy="0 0 0" />
      <mass
        value="25.57" />
      <inertia
        ixx="1.8986"
        ixy="-2.5488E-17"
        ixz="-1.6347E-17"
        iyy="0.98857"
        iyz="-0.49703"
        izz="1.0528" />
    </inertial>
    <visual>
      <origin
        xyz="0 0 0"
        rpy="0 0 0" />
      <geometry>
        <mesh
          filename="package://urdf/meshes/base_link.STL" />
      </geometry>
      <material
        name="">
        <color
          rgba="0.79216 0.81961 0.93333 1" />
      </material>
    </visual>
    <collision>
      <origin
        xyz="0 0 0"
        rpy="0 0 0" />
      <geometry>
        <mesh
          filename="package://urdf/meshes/base_link.STL" />
      </geometry>
    </collision>
  </link>
  <link
    name="Empty_Link2">
    <inertial>
      <origin
        xyz="0.13438 0.11452 -4.198E-16"
        rpy="0 0 0" />
      <mass
        value="0.31213" />
      <inertia
        ixx="0.00062851"
        ixy="0.00091576"
        ixz="3.9641E-18"
        iyy="0.0020652"
        iyz="-1.7754E-18"
        izz="0.0026437" />
    </inertial>
    <visual>
      <origin
        xyz="0 0 0"
        rpy="0 0 0" />
      <geometry>
        <mesh
          filename="package://urdf/meshes/Empty_Link2.STL" />
      </geometry>
      <material
        name="">
        <color
          rgba="0.79216 0.81961 0.93333 1" />
      </material>
    </visual>
    <collision>
      <origin
        xyz="0 0 0"
        rpy="0 0 0" />
      <geometry>
        <mesh
          filename="package://urdf/meshes/Empty_Link2.STL" />
      </geometry>
    </collision>
  </link>
  <joint
    name="joint_1"
    type="continuous">
    <origin
      xyz="-0.049484 0.32456 0.035262"
      rpy="1.5708 0 -1.4705" />
    <parent
      link="base_link" />
    <child
      link="Empty_Link2" />
    <axis
      xyz="0 1 0" />
  </joint>
  <link
    name="Empty_Link3">
    <inertial>
      <origin
        xyz="0.054607 0.20041 2.4286E-17"
        rpy="0 0 0" />
      <mass
        value="0.13658" />
      <inertia
        ixx="0.0002079"
        ixy="0.0003368"
        ixz="3.8964E-19"
        iyy="0.00083751"
        iyz="-1.7737E-19"
        izz="0.0010315" />
    </inertial>
    <visual>
      <origin
        xyz="0 0 0"
        rpy="0 0 0" />
      <geometry>
        <mesh
          filename="package://urdf/meshes/Empty_Link3.STL" />
      </geometry>
      <material
        name="">
        <color
          rgba="0.79216 0.81961 0.93333 1" />
      </material>
    </visual>
    <collision>
      <origin
        xyz="0 0 0"
        rpy="0 0 0" />
      <geometry>
        <mesh
          filename="package://urdf/meshes/Empty_Link3.STL" />
      </geometry>
    </collision>
  </link>
  <joint
    name="Joint_2"
    type="continuous">
    <origin
      xyz="0.065189 -0.12006 0"
      rpy="-0.010124 -0.0084947 4.3001E-05" />
    <parent
      link="Empty_Link2" />
    <child
      link="Empty_Link3" />
    <axis
      xyz="0.76604 0.64279 0" />
  </joint>
  <link
    name="Empty_Link4">
    <inertial>
      <origin
        xyz="1.885E-08 0.080071 3.6481E-08"
        rpy="0 0 0" />
      <mass
        value="0.10029" />
      <inertia
        ixx="0.00063967"
        ixy="1.362E-12"
        ixz="3.5609E-13"
        iyy="1.2935E-05"
        iyz="3.2834E-12"
        izz="0.00064015" />
    </inertial>
    <visual>
      <origin
        xyz="0 0 0"
        rpy="0 0 0" />
      <geometry>
        <mesh
          filename="package://urdf/meshes/Empty_Link4.STL" />
      </geometry>
      <material
        name="">
        <color
          rgba="0.79216 0.81961 0.93333 1" />
      </material>
    </visual>
    <collision>
      <origin
        xyz="0 0 0"
        rpy="0 0 0" />
      <geometry>
        <mesh
          filename="package://urdf/meshes/Empty_Link4.STL" />
      </geometry>
    </collision>
  </link>
  <joint
    name="joint_3"
    type="continuous">
    <origin
      xyz="-0.065189 0 0"
      rpy="0 -0.84544 0" />
    <parent
      link="Empty_Link3" />
    <child
      link="Empty_Link4" />
    <axis
      xyz="0 1 0" />
  </joint>
</robot>